{"content": {"suites": {"0": {"status": {"total_pass": 0, "total_skip": 0, "total_xpass": 0, "total_xfail": 0, "total_rerun": 0, "total_fail": 1, "total_error": 0}, "tests": {"0": {"status": "FAIL", "message": "           ConnectionRefusedError: [WinError 10061] No connection could be made because the target machine actively refused it\n       urllib3.exceptions.NewConnectionError: <urllib3.connection.HTTPConnection object at 0x0000019E1D96A100>: Failed to establish a new connection: [WinError 10061] No connection could be made because the target machine actively refused it\n       urllib3.exceptions.MaxRetryError: HTTPConnectionPool(host='127.0.0.1', port=58569): Max retries exceeded with url: /session/b81ccfa7-2406-4301-bffe-b8f5e01b54ad/timeouts (Caused by NewConnectionError('<urllib3.connection.HTTPConnection object at 0x0000019E1D96A100>: Failed to establish a new connection: [WinError 10061] No connection could be made because the target machine actively refused it'))\n", "test_name": "test_me", "rerun": "0"}}, "suite_name": "test_selenium.py"}}}, "date": "September 04, 2022", "start_time": 1662250340.3366535, "total_suite": 1, "status": "FAIL", "status_list": {"pass": "0", "fail": "1", "skip": "0", "error": "0", "xpass": "0", "xfail": "0", "rerun": "0"}, "total_tests": "1"}